Workbook

Sheet JANUARY
A1: CASH DISBURSEMENT RECORD
A3: ROMANA PANGAN DISTRICT HOSPITAL
A4: (Agency)
A6: ELAINE JUSTINA L. ABRIOL | D6: Nutritionist-Dietitian II | F6: Nutrition and Dietetics Service
A7: Accountable Officer | D7: Official Designation | F7: Station
A8: Date | B8: Reference No./O.R. No/Check No. | C8: Name of Payee | D8: Nature of Payment (Short Description) | E8: Cash Advance Received/ Replenishment | F8: Disbursements | G8: Cash Advance Balance
D9: Beginning Balance | G9: =E9 -> 0
G10: =G9+E10-F10 -> 0
G11: =G10+E11-F11 -> 0
G12: =G11+E12-F12 -> 0
G13: =G12+E13-F13 -> 0
G14: =G13+E14-F14 -> 0
G15: =G14+E15-F15 -> 0
G16: =G15+E16-F16 -> 0
G17: =G16+E17-F17 -> 0
G18: =G17+E18-F18 -> 0
G19: =G18+E19-F19 -> 0
G20: =G19+E20-F20 -> 0
G21: =G20+E21-F21 -> 0
... G47: =G46+E47-F47 -> 0
D48: Ending Balance | G48: =G47+E48-F48 -> 0

Sheet FEBRUARY
A1: CASH DISBURSEMENT RECORD
A3: ROMANA PANGAN DISTRICT HOSPITAL
A4: (Agency)
A6: ELAINE JUSTINA L. ABRIOL | D6: Nutritionist-Dietitian II | F6: Nutrition and Dietetics Service
A7: Accountable Officer | D7: Official Designation | F7: Station
A8: Date | B8: Reference No./O.R. No/Check No. | C8: Name of Payee | D8: Nature of Payment (Short Description) | E8: Cash Advance Received/ Replenishment | F8: Disbursements | G8: Cash Advance Balance
D9: Balance Forwared | E9: =JANUARY!G48 -> 0 | G9: =E9 -> 0
G10: =G9+E10-F10 -> 0
G11: =G10+E11-F11 -> 0
G12: =G11+E12-F12 -> 0
G13: =G12+E13-F13 -> 0
G14: =G13+E14-F14 -> 0
G15: =G14+E15-F15 -> 0
G16: =G15+E16-F16 -> 0
G17: =G16+E17-F17 -> 0
G18: =G17+E18-F18 -> 0
G19: =G18+E19-F19 -> 0
G20: =G19+E20-F20 -> 0
G21: =G20+E21-F21 -> 0
... G47: =G46+E47-F47 -> 0
D48: Ending Balance | G48: =G47+E48-F48 -> 0

Sheet MARCH
A1: CASH DISBURSEMENT RECORD
A3: ROMANA PANGAN DISTRICT HOSPITAL
A4: (Agency)
A6: ELAINE JUSTINA L. ABRIOL | D6: Nutritionist-Dietitian II | F6: Nutrition and Dietetics Service
A7: Accountable Officer | D7: Official Designation | F7: Station
A8: Date | B8: Reference No./O.R. No/Check No. | C8: Name of Payee | D8: Nature of Payment (Short Description) | E8: Cash Advance Received/ Replenishment | F8: Disbursements | G8: Cash Advance Balance
D9: Balance Forwared | E9: =FEBRUARY!G48 -> 0 | G9: =E9 -> 0
G10: =G9+E10-F10 -> 0
G11: =G10+E11-F11 -> 0
G12: =G11+E12-F12 -> 0
G13: =G12+E13-F13 -> 0
G14: =G13+E14-F14 -> 0
G15: =G14+E15-F15 -> 0
G16: =G15+E16-F16 -> 0
G17: =G16+E17-F17 -> 0
G18: =G17+E18-F18 -> 0
G19: =G18+E19-F19 -> 0
G20: =G19+E20-F20 -> 0
G21: =G20+E21-F21 -> 0
... G47: =G46+E47-F47 -> 0
D48: Ending Balance | G48: =G47+E48-F48 -> 0

Sheet APRIL
A1: CASH DISBURSEMENT RECORD
A3: ROMANA PANGAN DISTRICT HOSPITAL
A4: (Agency)
A6: ELAINE JUSTINA L. ABRIOL | D6: Nutritionist-Dietitian II | F6: Nutrition and Dietetics Service
A7: Accountable Officer | D7: Official Designation | F7: Station
A8: Date | B8: Reference No./O.R. No/Check No. | C8: Name of Payee | D8: Nature of Payment (Short Description) | E8: Cash Advance Received/ Replenishment | F8: Disbursements | G8: Cash Advance Balance
D9: Balance Forwared | E9: =MARCH!G48 -> 0 | G9: =E9 -> 0
G10: =G9+E10-F10 -> 0
G11: =G10+E11-F11 -> 0
G12: =G11+E12-F12 -> 0
G13: =G12+E13-F13 -> 0
G14: =G13+E14-F14 -> 0
G15: =G14+E15-F15 -> 0
G16: =G15+E16-F16 -> 0
G17: =G16+E17-F17 -> 0
G18: =G17+E18-F18 -> 0
G19: =G18+E19-F19 -> 0
G20: =G19+E20-F20 -> 0
G21: =G20+E21-F21 -> 0
... G47: =G46+E47-F47 -> 0
D48: Ending Balance | G48: =G47+E48-F48 -> 0

Sheet MAY
A1: CASH DISBURSEMENT RECORD
A3: ROMANA PANGAN DISTRICT HOSPITAL
A4: (Agency)
A6: ELAINE JUSTINA L. ABRIOL | D6: Nutritionist-Dietitian II | F6: Nutrition and Dietetics Service
A7: Accountable Officer | D7: Official Designation | F7: Station
A8: Date | B8: Reference No./O.R. No/Check No. | C8: Name of Payee | D8: Nature of Payment (Short Description) | E8: Cash Advance Received/ Replenishment | F8: Disbursements | G8: Cash Advance Balance
A9: 46143 | D9: Balance Forwared | E9: 18930 | G9: =E9 -> 18930
B10: 3539721 | C10: Elaine Justina L. Abriol | D10: Replenishment | E10: 55025 | G10: =G9+E10-F10 -> 73955
B11: 3539728 | C11: Elaine Justina L. Abriol | D11: Replenishment | E11: 64893 | G11: =G10+E11-F11 -> 138848
B12: 2918 | C12: Gloria T.M. Gen. Mdse … | D12: assorted vegetables | F12: 6015 | G12: =G11+E12-F12 -> 132833
B13: 3118 | C13: MACMA Trading | D13: meat | F13: 14120 | G13: =G12+E13-F13 -> 118713
B14: 3119 | C14: MACMA Trading | D14: meat | F14: 14580 | G14: =G13+E14-F14 -> 104133
B15: 3120 | C15: MACMA Trading | D15: meat | F15: 11760 | G15: =G14+E15-F15 -> 92373
B16: 1371 | C16: RPDH-MPC | D16: groceries | F16: 7785 | G16: =G15+E16-F16 -> 84588
B17: 1372 | C17: RPDH-MPC | D17: groceries | F17: 6215 | G17: =G16+E17-F17 -> 78373
B18: 1373 | C18: RPDH-MPC | D18: groceries | F18: 2805 | G18: =G17+E18-F18 -> 75568
B19: 1374 | C19: RPDH-MPC | D19: roll bag | F19: 780 | G19: =G18+E19-F19 -> 74788
B20: 1283 | C20: SAMEJ Rice Store and Gen.. | D20: rice | F20: 8460 | G20: =G19+E20-F20 -> 66328
B21: 35 | C21: Lolita R. Cayanan | D21: saba | F21: 1000 | G21: =G20+E21-F21 -> 65328
B22: 569 | C22: SAMEJ Rice Store and Gen.. | D22: paper meal box | F22: 14400 | G22: =G21+E22-F22 -> 50928
A23: 46150 | B23: 3539731 | C23: Elaine Justina L Abriol | D23: Replenishment | E23: 70058 | G23: =G22+E23-F23 -> 120986
B24: 2924 | C24: Gloria T.M. Gen. Mdse … | D24: assorted vegetables | F24: 6805 | G24: =G23+E24-F24 -> 114181
B25: 3128 | C25: MACMA Trading | D25: meat | F25: 14490 | G25: =G24+E25-F25 -> 99691
B26: 3129 | C26: MACMA Trading | D26: meat | F26: 13200 | G26: =G25+E26-F26 -> 86491
B27: 3130 | C27: MACMA Trading | D27: meat | F27: 11340 | G27: =G26+E27-F27 -> 75151
B28: 1378 | C28: RPDH-MPC | D28: groceries | F28: 7418 | G28: =G27+E28-F28 -> 67733
B29: 1379 | C29: RPDH-MPC | D29: groceries | F29: 5135 | G29: =G28+E29-F29 -> 62598
B30: 1380 | C30: RPDH-MPC | D30: roll bag | F30: 390 | G30: =G29+E30-F30 -> 62208
B31: 1285 | C31: SAMEJ Rice Store and Gen.. | D31: rice | F31: 5640 | G31: =G30+E31-F31 -> 56568
B32: 37 | C32: Lolita R. Cayanan | D32: saba | F32: 1000 | G32: =G31+E32-F32 -> 55568
B33: 1381 | C33: RPDH-MPC | D33: LPG | F33: 8500 | G33: =G32+E33-F33 -> 47068
A34: 46154 | B34: 2928 | C34: Gloria T.M. Gen. Mdse … | D34: assorted vegetables | F34: 5670 | G34: =G33+E34-F34 -> 41398
B35: 3132 | C35: MACMA Trading | D35: meat assorted | F35: 11760 | G35: =G34+E35-F35 -> 29638
B36: 3133 | C36: MACMA Trading | D36: meat assorted | F36: 7920 | G36: =G35+E36-F36 -> 21718
B37: 1382 | C37: RPDH-MPC | D37: groceries | F37: 6600 | G37: =G36+E37-F37 -> 15118
B38: 1383 | C38: RPDH-MPC | D38: groceries | F38: 1420 | G38: =G37+E38-F38 -> 13698
B39: 1286 | C39: SAMEJ Rice Store and Gen.. | D39: rice | F39: 5640 | G39: =G38+E39-F39 -> 8058
B40: 38 | C40: Lolita R. Cayanan | D40: saba | F40: 1000 | G40: =G39+E40-F40 -> 7058
B41: 1287 | C41: SAMEJ Rice Store and Gen.. | D41: paper meal box | F41: 4800 | G41: =G40+E41-F41 -> 2258
A42: 46160 | B42: 3539746 | C42: Elaine Justina L. Abriol | D42: replenishment | E42: 66775 | G42: =G41+E42-F42 -> 69033
...

Sheet JUNE
A1: CASH DISBURSEMENT RECORD
A3: ROMANA PANGAN DISTRICT HOSPITAL
A4: (Agency)
A6: ELAINE JUSTINA L. ABRIOL | D6: Nutritionist-Dietitian II | F6: Nutrition and Dietetics Service
A7: Accountable Officer | D7: Official Designation | F7: Station
A8: Date | B8: Reference No./O.R. No/Check No. | C8: Name of Payee | D8: Nature of Payment (Short Description) | E8: Cash Advance Received/ Replenishment | F8: Disbursements | G8: Cash Advance Balance
A9: 46174 | D9: Balance Forwared | E9: 44971.5 | G9: =E9 -> 44971.5
A10: 46175 | C10: Gloria T.M. Gen. Mdse … | D10: assorted vegetables | F10: 5600 | G10: =G9+E10-F10 -> 39371.5
B11: 3151 | C11: MACMA Trading | D11: meat | F11: 13320 | G11: =G10+E11-F11 -> 26051.5
B12: 3152 | C12: MACMA Trading | D12: meat | F12: 13560 | G12: =G11+E12-F12 -> 12491.5
B13: 1401 | C13: RPDH-MPC | D13: groceries | F13: 8205 | G13: =G12+E13-F13 -> 4286.5
B14: 1402 | C14: RPDH-MPC | D14: groceries | F14: 1601 | G14: =G13+E14-F14 -> 2685.5
B15: 3539764 | C15: Elaine Justina L. Abriol | D15: Replenishment | E15: 44810 | G15: =G14+E15-F15 -> 47495.5
B16: 1293 | C16: SAMEJ Rice Store and Gen.. | D16: rice | F16: 5480 | G16: =G15+E16-F16 -> 42015.5
B17: 45 | C17: Lolita R. Cayanan | D17: saba | F17: 1000 | G17: =G16+E17-F17 -> 41015.5
B18: 3539772 | C18: Elaine Justina L. Abriol | D18: Replenishment | E18: 44660 | G18: =G17+E18-F18 -> 85675.5
C19: Gloria T.M. Gen. Mdse … | D19: assorted vegetables | F19: 7090 | G19: =G18+E19-F19 -> 78585.5
B20: 3155 | C20: MACMA Trading | D20: meat | F20: 12890 | G20: =G19+E20-F20 -> 65695.5
B21: 3157 | C21: MACMA Trading | D21: meat | F21: 14280 | G21: =G20+E21-F21 -> 51415.5
B22: 3158 | C22: MACMA Trading | D22: meat | F22: 13470 | G22: =G21+E22-F22 -> 37945.5
B23: 1403 | C23: RPDH-MPC | D23: groceries | F23: 6100 | G23: =G22+E23-F23 -> 31845.5
B24: 1404 | C24: RPDH-MPC | D24: groceries | F24: 6970 | G24: =G23+E24-F24 -> 24875.5
B25: 1406 | C25: RPDH-MPC | D25: groceries | F25: 595 | G25: =G24+E25-F25 -> 24280.5
B26: 1405 | C26: RPDH-MPC | D26: roll bag | F26: 390 | G26: =G25+E26-F26 -> 23890.5
B27: 1405 | C27: RPDH-MPC | D27: LPG | F27: 14000 | G27: =G26+E27-F27 -> 9890.5
B28: 46 | C28: Lolita R. Cayanan | D28: saba | F28: 1000 | G28: =G27+E28-F28 -> 8890.5
G29: =G28+E29-F29 -> 8890.5
G30: =G29+E30-F30 -> 8890.5
G31: =G30+E31-F31 -> 8890.5
G32: =G31+E32-F32 -> 8890.5
G33: =G32+E33-F33 -> 8890.5
G34: =G33+E34-F34 -> 8890.5
G35: =G34+E35-F35 -> 8890.5
G36: =G35+E36-F36 -> 8890.5
G37: =G36+E37-F37 -> 8890.5
G38: =G37+E38-F38 -> 8890.5
G39: =G38+E39-F39 -> 8890.5
G40: =G39+E40-F40 -> 8890.5
... G47: =G46+E47-F47 -> 8890.5
D48: Ending Balance | G48: =G47+E48-F48 -> 8890.5

Sheet JULY
A1: CASH DISBURSEMENT RECORD
A3: ROMANA PANGAN DISTRICT HOSPITAL
A4: (Agency)
A6: ELAINE JUSTINA L. ABRIOL | D6: Nutritionist-Dietitian II | F6: Nutrition and Dietetics Service
A7: Accountable Officer | D7: Official Designation | F7: Station
A8: Date | B8: Reference No./O.R. No/Check No. | C8: Name of Payee | D8: Nature of Payment (Short Description) | E8: Cash Advance Received/ Replenishment | F8: Disbursements | G8: Cash Advance Balance
D9: Balance Forwared | E9: =JUNE!G48 -> 8890.5 | G9: =E9 -> 8890.5
G10: =G9+E10-F10 -> 8890.5
G11: =G10+E11-F11 -> 8890.5
G12: =G11+E12-F12 -> 8890.5
G13: =G12+E13-F13 -> 8890.5
G14: =G13+E14-F14 -> 8890.5
G15: =G14+E15-F15 -> 8890.5
G16: =G15+E16-F16 -> 8890.5
G17: =G16+E17-F17 -> 8890.5
G18: =G17+E18-F18 -> 8890.5
G19: =G18+E19-F19 -> 8890.5
G20: =G19+E20-F20 -> 8890.5
G21: =G20+E21-F21 -> 8890.5
... G47: =G46+E47-F47 -> 8890.5
D48: Ending Balance | G48: =G47+E48-F48 -> 8890.5

Sheet AUGUST
A1: CASH DISBURSEMENT RECORD
A3: ROMANA PANGAN DISTRICT HOSPITAL
A4: (Agency)
A6: ELAINE JUSTINA L. ABRIOL | D6: Nutritionist-Dietitian II | F6: Nutrition and Dietetics Service
A7: Accountable Officer | D7: Official Designation | F7: Station
A8: Date | B8: Reference No./O.R. No/Check No. | C8: Name of Payee | D8: Nature of Payment (Short Description) | E8: Cash Advance Received/ Replenishment | F8: Disbursements | G8: Cash Advance Balance
D9: Balance Forwared | E9: =JULY!G48 -> 8890.5 | G9: =E9 -> 8890.5
G10: =G9+E10-F10 -> 8890.5
G11: =G10+E11-F11 -> 8890.5
G12: =G11+E12-F12 -> 8890.5
G13: =G12+E13-F13 -> 8890.5
G14: =G13+E14-F14 -> 8890.5
G15: =G14+E15-F15 -> 8890.5
G16: =G15+E16-F16 -> 8890.5
G17: =G16+E17-F17 -> 8890.5
G18: =G17+E18-F18 -> 8890.5
G19: =G18+E19-F19 -> 8890.5
G20: =G19+E20-F20 -> 8890.5
G21: =G20+E21-F21 -> 8890.5
... G47: =G46+E47-F47 -> 8890.5
D48: Ending Balance | G48: =G47+E48-F48 -> 8890.5

Sheet SEPTEMBER
A1: CASH DISBURSEMENT RECORD
A3: ROMANA PANGAN DISTRICT HOSPITAL
A4: (Agency)
A6: ELAINE JUSTINA L. ABRIOL | D6: Nutritionist-Dietitian II | F6: Nutrition and Dietetics Service
A7: Accountable Officer | D7: Official Designation | F7: Station
A8: Date | B8: Reference No./O.R. No/Check No. | C8: Name of Payee | D8: Nature of Payment (Short Description) | E8: Cash Advance Received/ Replenishment | F8: Disbursements | G8: Cash Advance Balance
D9: Balance Forwared | E9: =AUGUST!G48 -> 8890.5 | G9: =E9 -> 8890.5
G10: =G9+E10-F10 -> 8890.5
G11: =G10+E11-F11 -> 8890.5
G12: =G11+E12-F12 -> 8890.5
G13: =G12+E13-F13 -> 8890.5
G14: =G13+E14-F14 -> 8890.5
G15: =G14+E15-F15 -> 8890.5
G16: =G15+E16-F16 -> 8890.5
G17: =G16+E17-F17 -> 8890.5
G18: =G17+E18-F18 -> 8890.5
G19: =G18+E19-F19 -> 8890.5
G20: =G19+E20-F20 -> 8890.5
G21: =G20+E21-F21 -> 8890.5
... G47: =G46+E47-F47 -> 8890.5
D48: Ending Balance | G48: =G47+E48-F48 -> 8890.5

Sheet OCTOBER
A1: CASH DISBURSEMENT RECORD
A3: ROMANA PANGAN DISTRICT HOSPITAL
A4: (Agency)
A6: ELAINE JUSTINA L. ABRIOL | D6: Nutritionist-Dietitian II | F6: Nutrition and Dietetics Service
A7: Accountable Officer | D7: Official Designation | F7: Station
A8: Date | B8: Reference No./O.R. No/Check No. | C8: Name of Payee | D8: Nature of Payment (Short Description) | E8: Cash Advance Received/ Replenishment | F8: Disbursements | G8: Cash Advance Balance
D9: Balance Forwared | E9: =SEPTEMBER!G48 -> 8890.5 | G9: =E9 -> 8890.5
G10: =G9+E10-F10 -> 8890.5
G11: =G10+E11-F11 -> 8890.5
G12: =G11+E12-F12 -> 8890.5
G13: =G12+E13-F13 -> 8890.5
G14: =G13+E14-F14 -> 8890.5
G15: =G14+E15-F15 -> 8890.5
G16: =G15+E16-F16 -> 8890.5
G17: =G16+E17-F17 -> 8890.5
G18: =G17+E18-F18 -> 8890.5
G19: =G18+E19-F19 -> 8890.5
G20: =G19+E20-F20 -> 8890.5
G21: =G20+E21-F21 -> 8890.5
... G47: =G46+E47-F47 -> 8890.5
D48: Ending Balance | G48: =G47+E48-F48 -> 8890.5

Sheet NOVEMBER
A1: CASH DISBURSEMENT RECORD
A3: ROMANA PANGAN DISTRICT HOSPITAL
A4: (Agency)
A6: ELAINE JUSTINA L. ABRIOL | D6: Nutritionist-Dietitian II | F6: Nutrition and Dietetics Service
A7: Accountable Officer | D7: Official Designation | F7: Station
A8: Date | B8: Reference No./O.R. No/Check No. | C8: Name of Payee | D8: Nature of Payment (Short Description) | E8: Cash Advance Received/ Replenishment | F8: Disbursements | G8: Cash Advance Balance
D9: Balance Forwared | E9: =OCTOBER!G48 -> 8890.5 | G9: =E9 -> 8890.5
G10: =G9+E10-F10 -> 8890.5
G11: =G10+E11-F11 -> 8890.5
G12: =G11+E12-F12 -> 8890.5
G13: =G12+E13-F13 -> 8890.5
G14: =G13+E14-F14 -> 8890.5
G15: =G14+E15-F15 -> 8890.5
G16: =G15+E16-F16 -> 8890.5
G17: =G16+E17-F17 -> 8890.5
G18: =G17+E18-F18 -> 8890.5
G19: =G18+E19-F19 -> 8890.5
G20: =G19+E20-F20 -> 8890.5
G21: =G20+E21-F21 -> 8890.5
... G47: =G46+E47-F47 -> 8890.5
D48: Ending Balance | G48: =G47+E48-F48 -> 8890.5

Sheet DECEMBER
A1: CASH DISBURSEMENT RECORD
A3: ROMANA PANGAN DISTRICT HOSPITAL
A4: (Agency)
A6: ELAINE JUSTINA L. ABRIOL | D6: Nutritionist-Dietitian II | F6: Nutrition and Dietetics Service
A7: Accountable Officer | D7: Official Designation | F7: Station
A8: Date | B8: Reference No./O.R. No/Check No. | C8: Name of Payee | D8: Nature of Payment (Short Description) | E8: Cash Advance Received/ Replenishment | F8: Disbursements | G8: Cash Advance Balance
G9: =E9 -> 0
G10: =G9+E10-F10 -> 0
G11: =G10+E11-F11 -> 0
G12: =G11+E12-F12 -> 0
G13: =G12+E13-F13 -> 0
G14: =G13+E14-F14 -> 0
G15: =G14+E15-F15 -> 0
G16: =G15+E16-F16 -> 0
G17: =G16+E17-F17 -> 0
G18: =G17+E18-F18 -> 0
G19: =G18+E19-F19 -> 0
G20: =G19+E20-F20 -> 0
G21: =G20+E21-F21 -> 0
... G47: =G46+E47-F47 -> 0
D48: Ending Balance | G48: =G47+E48-F48 -> 0
